File: data.csv
Resistance[Ohm],Time_r [s],Position [mm],Time_p[s],Force [N],Time_f[s],Stress[kPa],Strain [mm/mm]
7324121.1,0.047991276,0,0.004029751,-0.098686382,0.354815483,-2467.159549,1
6159364.1,0.402302504,0,0.358843803,-0.332246768,0.446760893,-8306.169198,1
6062177.3,0.492735624,-0.344,0.448759317,-0.406162117,0.537712336,-10154.05293,1.0086
6079638.7,0.585685492,-0.436,0.542713642,-0.160484461,0.628657341,-4012.111518,1.0109
6194161.7,0.674647093,-0.528,0.631686687,-0.290745117,0.76651001,-7268.627924,1.0132
6293980.3,0.816012383,-0.62,0.772537708,-0.265601781,1.041393518,-6640.044525,1.0155
6121245.7,1.088375092,-0.756,1.044390917,-0.122012127,1.132359266,-3050.303184,1.0189
6147270.6,1.181868792,-1.032,1.139387846,0.02400098,1.225383997,600.0245082,1.0258
5968666.8,1.270433903,-1.124,1.227348089,-0.088992566,1.314519405,-2224.814142,1.0281
6054971.4,1.363468409,-1.216,1.320485592,-0.316797248,1.45343256,-7919.931205,1.0304
6247193.3,1.499400854,-1.304,1.455430508,0.007036802,1.727340221,175.920046,1.0326
6348661.9,1.774304152,-1.444,1.731306314,0.362981618,1.818305731,9074.540458,1.0361
6323702.2,1.865314484,-1.716,1.821329832,-0.082025135,1.909299135,-2050.62838,1.0429
6270043.4,1.9562428,-1.808,1.91326952,0.41326829,2.000215769,10331.70726,1.0452
6487956.3,2.044711828,-1.9,2.002215385,0.068229017,2.12719059,1705.725427,1.0475
6822648.4,2.174169302,-1.992,2.131188393,0.496271592,2.399501562,12406.7898,1.0498
6842031.3,2.445463419,-2.116,2.402503729,0.162137862,2.489421606,4053.446557,1.0529
6863544.7,2.533405781,-2.392,2.490421295,0.399030498,2.577388048,9975.76244,1.0598
6769177.6,2.624360085,-2.48,2.581388474,0.044297408,2.668329716,1107.435204,1.062
6758483.6,2.713819742,-2.568,2.670329094,0.202427786,2.79628849,5060.694655,1.0642
6713493.4,2.84422946,-2.66,2.801254749,0.313906673,3.056376934,7847.666835,1.0665
6808549.2,3.100851297,-2.788,3.058376312,0.261802411,3.144325495,6545.060273,1.0697
6788581.4,3.191807985,-3.048,3.148349524,0.204548309,3.235266209,5113.707713,1.0762
6685233.1,3.280506134,-3.136,3.237265348,0.363890414,3.324777842,9097.26034,1.0784
6602165.8,3.371182919,-3.228,3.327752829,0.604721162,3.454477549,15118.02904,1.0807
6497835.8,3.499433756,-3.316,3.456474781,0.796779897,3.714290857,19919.49742,1.0829
6582845.5,3.762259722,-3.448,3.71928525,0.510206453,3.806265354,12755.16133,1.0862
6528519,3.851223946,-3.708,3.808233261,0.660460605,3.895183802,16511.51513,1.0927
6630050.2,3.942159176,-3.8,3.899181366,0.381460456,3.986136198,9536.51139,1.095
6613131.9,4.031123877,-3.888,3.988137007,0.395698248,4.110093355,9892.456206,1.0972
6713765,4.156610966,-3.98,4.114088058,0.60441823,4.370066643,15110.45575,1.0995
6676836.6,4.416039705,-4.104,4.372064829,0.679242374,4.460014343,16981.05936,1.1026
6790899.8,4.506963015,-4.364,4.463987589,0.516870952,4.550938606,12921.77379,1.1091
6729116.7,4.596424341,-4.452,4.552937984,0.585030597,4.64090991,14625.76494,1.1113
6835493.7,4.687870264,-4.544,4.644882679,0.309362697,4.768812895,7734.067426,1.1136
6843681.4,4.81531024,-4.636,4.77183485,0.709232619,5.040648699,17730.81546,1.1159
6723707.1,5.087121487,-4.764,5.043646812,0.960060115,5.131627321,24001.50287,1.1191
6777887.4,5.176589251,-5.036,5.133600712,0.795265238,5.220575809,19881.63095,1.1259
6688679.4,5.267523527,-5.124,5.224548817,0.688027395,5.310498238,17200.68488,1.1281
6668565.5,5.356481791,-5.216,5.313522339,0.487486571,5.439449787,12187.16428,1.1304
6871982.9,5.48639369,-5.304,5.44342041,0.969450999,5.696275949,24236.27498,1.1326
6937609.5,5.741276979,-5.436,5.698302746,1.132731217,5.784250975,28318.28043,1.1359
7013783.6,5.831698179,-5.692,5.788221598,1.206040703,5.876173496,30151.01757,1.1423
6995152.6,5.923158884,-5.78,5.879196882,0.920981918,5.967121124,23024.54795,1.1445
7223905.9,6.014090061,-5.872,5.971117735,0.529291154,6.096048355,13232.27885,1.1468
7189108.5,6.141346216,-5.964,6.098041534,1.174838732,6.355480194,29370.96829,1.1491
7294065,6.401465178,-6.092,6.358504057,0.909167579,6.44542861,22729.18948,1.1523
7217994.9,6.490412474,-6.352,6.447422981,1.247845285,6.534379005,31196.13214,1.1588
7271277.5,6.581362486,-6.44,6.538374424,0.939460755,6.62532568,23486.51888,1.161
7069719,6.66981101,-6.532,6.627322674,0.833131708,6.75125289,20828.2927,1.1633
7186685.6,6.799237013,-6.62,6.755250692,1.158783348,7.025119543,28969.58371,1.1655
7463311.8,7.070574999,-6.748,7.027091265,1.460806312,7.115043163,36520.1578,1.1687
7554086.1,7.1610291,-7.02,7.118036032,1.206040703,7.205030441,30151.01757,1.1755
7777868.4,7.249998808,-7.112,7.207025766,0.989747427,7.293971062,24743.68568,1.1778
7443427,7.340975046,-7.2,7.29700017,0.826164277,7.423856258,20654.10693,1.18
7400170.4,7.468156576,-7.292,7.424837351,1.30025248,7.682348013,32506.31199,1.1823
7663387.3,7.729339361,-7.42,7.685353041,1.359930036,7.774324417,33998.2509,1.1855
7880986.9,7.81927228,-7.68,7.776296377,1.086382658,7.863244057,27159.56645,1.192
7773043.6,7.912222147,-7.772,7.86924696,1.030643214,7.956196785,25766.08036,1.1943
7985525.9,8.001678705,-7.86,7.95821929,1.121522742,8.095114946,28038.06855,1.1965
8163398.2,8.144598722,-7.952,8.101110458,1.188167729,8.368590832,29704.19323,1.1988
8274809,8.413584232,-8.092,8.370621681,1.374470761,8.457546711,34361.76902,1.2023
8567601.6,8.504513979,-8.368,8.461538315,1.452021291,8.548489332,36300.53227,1.2092
8517786.7,8.592469454,-8.456,8.549494505,1.548959454,8.636441946,38723.98634,1.2114
8389290.5,8.683429956,-8.548,8.640467405,1.292679186,8.767392874,32316.97964,1.2137
8263843.4,8.812370062,-8.636,8.769369602,1.482617398,9.026271582,37065.43496,1.2159
8479730.2,9.074248314,-8.764,9.031275511,1.347206902,9.117221117,33680.17256,1.2191
8477453.6,9.162694216,-9.024,9.11921978,1.536539252,9.207175255,38413.48129,1.2256
8696369.2,9.255143881,-9.116,9.211172581,1.488373102,9.299115419,37209.32755,1.2279
8650209.4,9.344120741,-9.204,9.301144838,1.337816018,9.424048901,33445.40045,1.2301
9081105.9,9.473014355,-9.3,9.429039478,1.326910474,9.69670248,33172.76186,1.2325
9520044.1,9.741722584,-9.424,9.698701143,1.467167879,9.785645485,36679.19697,1.2356
9647392,9.832134008,-9.696,9.788674116,1.599246126,9.876594543,39981.15314,1.2424
9518331.4,9.922567844,-9.784,9.879590988,1.687096336,9.966542721,42177.40839,1.2446
9854443.3,10.01353002,-9.876,9.970571518,1.582584879,10.09446812,39564.62197,1.2469
9430000.4,10.13944507,-9.968,10.09647226,1.487767238,10.35631561,37194.18096,1.2492
9508639.9,10.40328932,-10,10.36031318,1.59833733,10.44726372,39958.43326,1.25
9741278.1,10.49225307,-10,10.44929361,1.557138611,10.53521228,38928.46528,1.25
9925563.4,10.58218741,-10,10.53920984,1.51048712,10.62616277,37762.17801,1.25
10045871,10.67163491,-10,10.62816119,1.38992028,10.75008821,34748.00701,1.25
9989582,10.79707789,-10,10.75408626,1.412943094,11.02493048,35323.57735,1.25
9832909,11.07080722,-10,11.02793074,1.555623952,11.11465454,38890.59881,1.25
9551186.9,11.16065717,-10,11.11668277,1.532601139,11.20560336,38315.02847,1.25
9534226.2,11.2510736,-10,11.20859766,1.524421981,11.29454994,38110.54953,1.25
9604531.7,11.33954906,-10,11.29657388,1.479285149,11.42248869,36982.12873,1.25
9444037.1,11.47244716,-10,11.42847157,1.483526194,11.69934654,37088.15484,1.25
9736912.8,11.74430823,-10,11.70132017,1.50018744,11.78826594,37504.68601,1.25
9829316.5,11.8352406,-10,11.79226828,1.50351969,11.87924337,37587.99225,1.25
9868730.5,11.92418599,-10,11.88121009,1.364474013,11.96816111,34111.85031,1.25
9875372.4,12.01563811,-10,11.97316575,1.611969259,12.09608746,40299.23149,1.25
9959107.6,12.14107943,-10,12.0980916,1.494431737,12.40195966,37360.79343,1.25
9776556.5,12.44959211,-10,12.40595746,1.490190692,12.49423456,37254.76731,1.25
9664895.1,12.53921556,-10,12.49622488,1.512001779,12.5831821,37800.04448,1.25
9652780.8,12.63064885,-10,12.5871737,1.505640212,12.67512274,37641.0053,1.25
9555009.2,12.72009659,-10,12.67712092,1.519272141,12.81404185,37981.80353,1.25
9540053.6,12.86404395,-10,12.82106853,1.463229766,13.11975789,36580.74415,1.25
9449968.9,13.16373158,-10,13.12075639,1.4502037,13.2077024,36255.09251,1.25
9551834.4,13.25569177,-10,13.21272874,1.493522942,13.29865456,37338.07354,1.25
9553171.1,13.34362817,-10,13.30065274,1.512304711,13.38760328,37807.61777,1.25
9570799.6,13.4360702,-10,13.39259434,1.449597837,13.51752281,36239.94592,1.25